<?xml version="1.0" encoding="UTF-8"?>
<mujoco model="ur5e_with_mop_and_dust">
  <compiler angle="radian" meshdir="assets" autolimits="true"/>
  <option integrator="implicitfast" timestep="0.01" viscosity="0.01"/>

  <!-- ================= DEFAULT SETTINGS ================= -->
  <default>
    <default class="ur5e">
      <default class="visual">
        <geom type="mesh" contype="0" conaffinity="0" group="2"/>
      </default>
      <default class="collision">
        <geom type="capsule" group="3"/>
        <default class="eef_collision">
          <geom type="cylinder"/>
        </default>
      </default>
      <joint axis="0 1 0" range="-6.28319 6.28319"/>
      <default class="joint_limited">
        <joint range="-3.1415 3.1415"/>
      </default>
      <default class="position">
        <position ctrlrange="-6.2831 6.2831" kp="2000" kv="100" forcerange="-150 150"/>
        <default class="position_limited">
          <position ctrlrange="-3.1415 3.1415"/>
        </default>
        <default class="position_small">
          <position kp="500" kv="25" forcerange="-28 28"/>
        </default>
      </default>
    </default>
    <!-- Improved dust particle physics for MuJoCo 3.3.5 -->
    <default class="dust">
      <geom type="sphere" size="0.008" density="600" friction="0.8 0.1 0.05" condim="3"
            contype="1" conaffinity="1" group="1"
            solref="0.02 1.0" solimp="0.9 0.95 0.001"/>
    </default>
  </default>

  <!-- ================= MATERIALS + MESHES ================= -->
  <asset>
    <material name="black" rgba="0.033 0.033 0.033 1"/>
    <material name="jointgray" rgba="0.278 0.278 0.278 1"/>
    <material name="linkgray" rgba="0.82 0.82 0.82 1"/>
    <material name="urblue" rgba="0.49 0.678 0.8 1"/>
    <material name="table_material" rgba="0.6 0.4 0.2 1"/>
    <material name="dust_material" rgba="0.4 0.3 0.2 0.8"/>

    <!-- Robot meshes -->
    <mesh file="base_0.obj"/>
    <mesh file="base_1.obj"/>
    <mesh file="shoulder_0.obj"/>
    <mesh file="shoulder_1.obj"/>
    <mesh file="shoulder_2.obj"/>
    <mesh file="upperarm_0.obj"/>
    <mesh file="upperarm_1.obj"/>
    <mesh file="upperarm_2.obj"/>
    <mesh file="upperarm_3.obj"/>
    <mesh file="forearm_0.obj"/>
    <mesh file="forearm_1.obj"/>
    <mesh file="forearm_2.obj"/>
    <mesh file="forearm_3.obj"/>
    <mesh file="wrist1_0.obj"/>
    <mesh file="wrist1_1.obj"/>
    <mesh file="wrist1_2.obj"/>
    <mesh file="wrist2_0.obj"/>
    <mesh file="wrist2_1.obj"/>
    <mesh file="wrist2_2.obj"/>
    <mesh file="wrist3.obj"/>

    <!-- Table and tool meshes -->
    <mesh file="test.stl" scale="0.28 0.29 0.1" name="table"/>
    <mesh name="base_mesh" file="mop_base.obj" scale="0.002 0.002 0.002"/>
    <mesh name="handle_mesh" file="mop_handle.obj" scale="0.002 0.002 0.002"/>
    <mesh name="dust_ball_mesh" file="simple_small_ball.stl" scale="0.005 0.005 0.005"/>
  </asset>

  <!-- ================= WORLD OBJECTS ================= -->
  <worldbody>
    <!-- Ground with proper contact properties -->
    <geom name="ground" type="plane" size="3 3 0.1" rgba="0.5 0.5 0.5 1" pos="0 0 0"
          solref="0.02 1.0" solimp="0.9 0.95 0.001" friction="0.9 0.1 0.05"/>

    <!-- Table positioned as base platform -->
    <body name="table" pos="0.3 0 0">
      <inertial mass="50" pos="0 0 0.05" diaginertia="10 10 5"/>
      <geom name="table_visual" type="mesh" mesh="table" material="table_material" class="visual"/>
      <geom name="table_collision" type="mesh" mesh="table"
            material="table_material" group="0" contype="1" conaffinity="1"
            solref="0.02 1.0" solimp="0.9 0.95 0.001" friction="0.7 0.1 0.05"/>
    </body>

    <!-- UR5e Robot mounted ON the table surface -->
    <body name="base" pos="-0.875 -0.2 0.5" quat="1 0 0 1" childclass="ur5e">
      <inertial mass="4" pos="0 0 0" diaginertia="0.0044 0.0044 0.0072"/>
      <geom mesh="base_0" material="black" class="visual"/>
      <geom mesh="base_1" material="jointgray" class="visual"/>
      <!-- Base collision geometry to sit on table -->
      <geom name="base_collision" type="cylinder" size="0.06 0.02" pos="0 0 -0.01"
            contype="1" conaffinity="1" group="3" friction="0.8 0.1 0.05"/>

      <body name="shoulder_link" pos="0 0 0.163">
        <inertial mass="3.7" pos="0 0 0" diaginertia="0.0102 0.0102 0.0066"/>
        <joint name="shoulder_pan" axis="0 0 1"/>
        <geom mesh="shoulder_0" material="urblue" class="visual"/>
        <geom mesh="shoulder_1" material="black" class="visual"/>
        <geom mesh="shoulder_2" material="jointgray" class="visual"/>

        <body name="upper_arm_link" pos="0 0.138 0" quat="1 0 1 0">
          <inertial mass="8.39" pos="0 0 0.2125" diaginertia="0.133 0.133 0.015"/>
          <joint name="shoulder_lift"/>
          <geom mesh="upperarm_0" material="linkgray" class="visual"/>
          <geom mesh="upperarm_1" material="black" class="visual"/>
          <geom mesh="upperarm_2" material="jointgray" class="visual"/>
          <geom mesh="upperarm_3" material="urblue" class="visual"/>

          <body name="forearm_link" pos="0 -0.131 0.425">
            <inertial mass="2.27" pos="0 0 0.196" diaginertia="0.031 0.031 0.004"/>
            <joint name="elbow" class="joint_limited"/>
            <geom mesh="forearm_0" material="urblue" class="visual"/>
            <geom mesh="forearm_1" material="linkgray" class="visual"/>
            <geom mesh="forearm_2" material="black" class="visual"/>
            <geom mesh="forearm_3" material="jointgray" class="visual"/>

            <body name="wrist_1_link" pos="0 0 0.392" quat="1 0 1 0">
              <inertial mass="1.219" pos="0 0.127 0" diaginertia="0.0025 0.0025 0.0021"/>
              <joint name="wrist_1"/>
              <geom mesh="wrist1_0" material="black" class="visual"/>
              <geom mesh="wrist1_1" material="urblue" class="visual"/>
              <geom mesh="wrist1_2" material="jointgray" class="visual"/>

              <body name="wrist_2_link" pos="0 0.127 0">
                <inertial mass="1.219" pos="0 0 0.1" diaginertia="0.0025 0.0025 0.0021"/>
                <joint name="wrist_2" axis="0 0 1"/>
                <geom mesh="wrist2_0" material="black" class="visual"/>
                <geom mesh="wrist2_1" material="urblue" class="visual"/>
                <geom mesh="wrist2_2" material="jointgray" class="visual"/>

                <body name="wrist_3_link" pos="0 0 0.1">
                  <inertial mass="0.188" pos="0 0.077 0" diaginertia="0.00013 0.0001 0.0001"/>
                  <joint name="wrist_3"/>
                  <geom mesh="wrist3" material="linkgray" class="visual"/>
                  <site name="ee_site" pos="0 0.08 0" size="0.01" rgba="1 0 0 1"/>

                  <!-- Mop tool attachment -->
                  <body name="mop_mount" pos="0 0.08 0" quat="1 0 0 1">
                    <body name="mop_tool" pos="0 -0.6 0">
                      <inertial mass="0.5" pos="0 0 0" diaginertia="0.01 0.01 0.01"/>
                      <geom type="mesh" mesh="handle_mesh" density="500" friction="0.8 0.1 0.1"/>

                      <body name="mop_head_y">
                        <joint name="mop_socket_y" type="hinge" axis="0 1 0" damping="0.5"
                              limited="true" range="-1.57079633 1.57079633"/>

                        <body name="mop_head_x">
                          <joint name="mop_socket_x" type="hinge" axis="1 0 0" damping="0.5"
                                limited="true" range="-1.57079633 1.57079633"/>

                          <inertial mass="0.2" pos="0 -0.05 -0.1" diaginertia="0.005 0.005 0.005"/>
                          <geom type="mesh" mesh="base_mesh" density="500" friction="0.8 0.1 0.1"
                                pos="0 -0.05 -0.1"/>
                        </body>
                      </body>
                    </body>
                  </body>
                </body>
              </body>
            </body>
          </body>
        </body>
      </body>
    </body>

    <!-- Dust particles properly positioned on table surface around the robot -->
    <!-- Distributed in a cleaning area away from robot base -->
          <!-- Dust balls (stable with solver parameters) -->
<!--    <body name="dust_1" pos="-1.2340 -0.6502 0.4">-->
<!--      <freejoint/>-->
<!--      <inertial mass="0.5" diaginertia="5e-5 5e-5 5e-5" pos="0 0 0"/>-->
<!--      <geom name="d1" class="dust" material="dust_material"/>-->
<!--    </body>-->

      <!-- Dust particles - stable until mop pushes them -->
    <body name="dust_1" pos="-1.2340 -0.6502 0.5">
      <freejoint/>
      <inertial mass="0.03" diaginertia="2e-5 2e-5 2e-5" pos="0 0 0"/>
      <geom name="d1" type="mesh" mesh="dust_ball_mesh" material="dust_material" class="dust"/>
    </body>

    <body name="dust_2" pos="-0.5004 -0.503 0.5">
      <freejoint/>
      <inertial mass="0.03" diaginertia="2e-5 2e-5 2e-5" pos="0 0 0"/>
      <geom name="d2" type="mesh" mesh="dust_ball_mesh" material="dust_material" class="dust"/>
    </body>

    <body name="dust_3" pos="-2.1001 -1.0000 0.5">
      <freejoint/>
      <inertial mass="0.03" diaginertia="2e-5 2e-5 2e-5" pos="0 0 0"/>
      <geom name="d3" type="mesh" mesh="dust_ball_mesh" material="dust_material" class="dust"/>
    </body>

    <body name="dust_4" pos="-0.3000 -0.600 0.5">
      <freejoint/>
      <inertial mass="0.03" diaginertia="2e-5 2e-5 2e-5" pos="0 0 0"/>
      <geom name="d4" type="mesh" mesh="dust_ball_mesh" material="dust_material" class="dust"/>
    </body>

    <body name="dust_5" pos="-1.8000 -0.2000 0.5">
      <freejoint/>
      <inertial mass="0.03" diaginertia="2e-5 2e-5 2e-5" pos="0 0 0"/>
      <geom name="d5" type="mesh" mesh="dust_ball_mesh" material="dust_material" class="dust"/>
    </body>

    <body name="dust_6" pos="-2.0000 -0.5000 0.5">
      <freejoint/>
      <inertial mass="0.03" diaginertia="2e-5 2e-5 2e-5" pos="0 0 0"/>
      <geom name="d6" type="mesh" mesh="dust_ball_mesh" material="dust_material" class="dust"/>
    </body>

    <body name="dust_7" pos="-0.7000 -1.2000 0.5">
      <freejoint/>
      <inertial mass="0.03" diaginertia="2e-5 2e-5 2e-5" pos="0 0 0"/>
      <geom name="d7" type="mesh" mesh="dust_ball_mesh" material="dust_material" class="dust"/>
    </body>

    <body name="dust_8" pos="-1.5000 -0.500 0.5">
      <freejoint/>
      <inertial mass="0.03" diaginertia="2e-5 2e-5 2e-5" pos="0 0 0"/>
      <geom name="d8" type="mesh" mesh="dust_ball_mesh" material="dust_material" class="dust"/>
    </body>

    <body name="dust_9" pos="-1.7500 -0.3000 0.5">
      <freejoint/>
      <inertial mass="0.03" diaginertia="2e-5 2e-5 2e-5" pos="0 0 0"/>
      <geom name="d9" type="mesh" mesh="dust_ball_mesh" material="dust_material" class="dust"/>
    </body>

    <body name="dust_10" pos="-0.9000 -0.900 0.5">
      <freejoint/>
      <inertial mass="0.03" diaginertia="2e-5 2e-5 2e-5" pos="0 0 0"/>
      <geom name="d10" type="mesh" mesh="dust_ball_mesh" material="dust_material" class="dust"/>
    </body>

    <body name="dust_11" pos="-1.0000 -0.5000 0.5">
      <freejoint/>
      <inertial mass="0.03" diaginertia="2e-5 2e-5 2e-5" pos="0 0 0"/>
      <geom name="d11" type="mesh" mesh="dust_ball_mesh" material="dust_material" class="dust"/>
    </body>

    <body name="dust_12" pos="-1.700 -1.0500 0.5">
      <freejoint/>
      <inertial mass="0.03" diaginertia="2e-5 2e-5 2e-5" pos="0 0 0"/>
      <geom name="d12" type="mesh" mesh="dust_ball_mesh" material="dust_material" class="dust"/>
    </body>

    <body name="dust_13" pos="-1.7500 -0.7500 0.5">
      <freejoint/>
      <inertial mass="0.03" diaginertia="2e-5 2e-5 2e-5" pos="0 0 0"/>
      <geom name="d13" type="mesh" mesh="dust_ball_mesh" material="dust_material" class="dust"/>
    </body>

    <body name="dust_14" pos="-0.2500 -0.2500 0.5">
      <freejoint/>
      <inertial mass="0.03" diaginertia="2e-5 2e-5 2e-5" pos="0 0 0"/>
      <geom name="d14" type="mesh" mesh="dust_ball_mesh" material="dust_material" class="dust"/>
    </body>

    <body name="dust_15" pos="-1.1000 -0.1500 0.5">
      <freejoint/>
      <inertial mass="0.03" diaginertia="2e-5 2e-5 2e-5" pos="0 0 0"/>
      <geom name="d15" type="mesh" mesh="dust_ball_mesh" material="dust_material" class="dust"/>
    </body>

    <body name="dust_16" pos="-1.2700 -0.3200 0.5">
      <freejoint/>
      <inertial mass="0.03" diaginertia="2e-5 2e-5 2e-5" pos="0 0 0"/>
      <geom name="d16" type="mesh" mesh="dust_ball_mesh" material="dust_material" class="dust"/>
    </body>

    <body name="dust_17" pos="-0.1608 -1.1246 0.5">
      <freejoint/>
      <inertial mass="0.03" diaginertia="2e-5 2e-5 2e-5" pos="0 0 0"/>
      <geom name="d17" type="mesh" mesh="dust_ball_mesh" material="dust_material" class="dust"/>
    </body>

    <body name="dust_18" pos="-1.5000 -1.0000 0.5">
      <freejoint/>
      <inertial mass="0.03" diaginertia="2e-5 2e-5 2e-5" pos="0 0 0"/>
      <geom name="d18" type="mesh" mesh="dust_ball_mesh" material="dust_material" class="dust"/>
    </body>

    <body name="dust_19" pos="-0.7008 -0.2003 0.5">
      <freejoint/>
      <inertial mass="0.03" diaginertia="2e-5 2e-5 2e-5" pos="0 0 0"/>
      <geom name="d19" type="mesh" mesh="dust_ball_mesh" material="dust_material" class="dust"/>
    </body>

    <body name="dust_20" pos="-2.1008 -0.9502 0.5">
      <freejoint/>
      <inertial mass="0.03" diaginertia="2e-5 2e-5 2e-5" pos="0 0 0"/>
      <geom name="d20" type="mesh" mesh="dust_ball_mesh" material="dust_material" class="dust"/>
    </body>

    <body name="dust_21" pos="-1.2000 -0.5000 0.5">
      <freejoint/>
      <inertial mass="0.03" diaginertia="2e-5 2e-5 2e-5" pos="0 0 0"/>
      <geom name="d21" type="mesh" mesh="dust_ball_mesh" material="dust_material" class="dust"/>
    </body>

    <body name="dust_22" pos="-0.4500 -1.0500 0.5">
      <freejoint/>
      <inertial mass="0.03" diaginertia="2e-5 2e-5 2e-5" pos="0 0 0"/>
      <geom name="d22" type="mesh" mesh="dust_ball_mesh" material="dust_material" class="dust"/>
    </body>

    <body name="dust_23" pos="-2.0000 -1.2000 0.5">
      <freejoint/>
      <inertial mass="0.03" diaginertia="2e-5 2e-5 2e-5" pos="0 0 0"/>
      <geom name="d23" type="mesh" mesh="dust_ball_mesh" material="dust_material" class="dust"/>
    </body>

    <body name="dust_24" pos="-0.1008 -1.1200 0.5">
      <freejoint/>
      <inertial mass="0.03" diaginertia="2e-5 2e-5 2e-5" pos="0 0 0"/>
      <geom name="d24" type="mesh" mesh="dust_ball_mesh" material="dust_material" class="dust"/>
    </body>

    <body name="dust_25" pos="-1.9000 -1.1000 0.5">
      <freejoint/>
      <inertial mass="0.03" diaginertia="2e-5 2e-5 2e-5" pos="0 0 0"/>
      <geom name="d25" type="mesh" mesh="dust_ball_mesh" material="dust_material" class="dust"/>
    </body>

    <body name="dust_26" pos="-0.2500 -1.0000 0.5">
      <freejoint/>
      <inertial mass="0.03" diaginertia="2e-5 2e-5 2e-5" pos="0 0 0"/>
      <geom name="d26" type="mesh" mesh="dust_ball_mesh" material="dust_material" class="dust"/>
    </body>

    <body name="dust_27" pos="-0.8000 -1.1000 0.5">
      <freejoint/>
      <inertial mass="0.03" diaginertia="2e-5 2e-5 2e-5" pos="0 0 0"/>
      <geom name="d27" type="mesh" mesh="dust_ball_mesh" material="dust_material" class="dust"/>
    </body>

    <body name="dust_28" pos="-1.3000 -0.3000 0.5">
      <freejoint/>
      <inertial mass="0.03" diaginertia="2e-5 2e-5 2e-5" pos="0 0 0"/>
      <geom name="d28" type="mesh" mesh="dust_ball_mesh" material="dust_material" class="dust"/>
    </body>

    <body name="dust_29" pos="-2.1500 -0.4000 0.5">
      <freejoint/>
      <inertial mass="0.03" diaginertia="2e-5 2e-5 2e-5" pos="0 0 0"/>
      <geom name="d29" type="mesh" mesh="dust_ball_mesh" material="dust_material" class="dust"/>
    </body>

    <body name="dust_30" pos="-1.0000 -0.1690 0.5">
      <freejoint/>
      <inertial mass="0.03" diaginertia="2e-5 2e-5 2e-5" pos="0 0 0"/>
      <geom name="d30" type="mesh" mesh="dust_ball_mesh" material="dust_material" class="dust"/>
    </body>

    <body name="dust_31" pos="-1.1000 -0.8000 0.5">
      <freejoint/>
      <inertial mass="0.03" diaginertia="2e-5 2e-5 2e-5" pos="0 0 0"/>
      <geom name="d31" type="mesh" mesh="dust_ball_mesh" material="dust_material" class="dust"/>
    </body>

    <body name="dust_32" pos="-2.0008 -1.1000 0.5">
      <freejoint/>
      <inertial mass="0.03" diaginertia="2e-5 2e-5 2e-5" pos="0 0 0"/>
      <geom name="d32" type="mesh" mesh="dust_ball_mesh" material="dust_material" class="dust"/>
    </body>

    <body name="dust_33" pos="-1.2000 -0.500 0.5">
      <freejoint/>
      <inertial mass="0.03" diaginertia="2e-5 2e-5 2e-5" pos="0 0 0"/>
      <geom name="d33" type="mesh" mesh="dust_ball_mesh" material="dust_material" class="dust"/>
    </body>

    <body name="dust_34" pos="-1.7000 -0.5500 0.5">
      <freejoint/>
      <inertial mass="0.03" diaginertia="2e-5 2e-5 2e-5" pos="0 0 0"/>
      <geom name="d34" type="mesh" mesh="dust_ball_mesh" material="dust_material" class="dust"/>
    </body>

    <body name="dust_35" pos="-2.1000 -0.2000 0.5">
      <freejoint/>
      <inertial mass="0.03" diaginertia="2e-5 2e-5 2e-5" pos="0 0 0"/>
      <geom name="d35" type="mesh" mesh="dust_ball_mesh" material="dust_material" class="dust"/>
    </body>

    <body name="dust_36" pos="-0.6000 -0.9000  0.5">
      <freejoint/>
      <inertial mass="0.03" diaginertia="2e-5 2e-5 2e-5" pos="0 0 0"/>
      <geom name="d36" type="mesh" mesh="dust_ball_mesh" material="dust_material" class="dust"/>
    </body>

    <body name="dust_37" pos="-2.2000 -1.2000 0.5">
      <freejoint/>
      <inertial mass="0.03" diaginertia="2e-5 2e-5 2e-5" pos="0 0 0"/>
      <geom name="d37" type="mesh" mesh="dust_ball_mesh" material="dust_material" class="dust"/>
    </body>

    <body name="dust_38" pos="-2.1000 -0.900 0.5">
      <freejoint/>
      <inertial mass="0.03" diaginertia="2e-5 2e-5 2e-5" pos="0 0 0"/>
      <geom name="d38" type="mesh" mesh="dust_ball_mesh" material="dust_material" class="dust"/>
    </body>

    <body name="dust_39" pos="-1.5000 -0.3000 0.5">
      <freejoint/>
      <inertial mass="0.03" diaginertia="2e-5 2e-5 2e-5" pos="0 0 0"/>
      <geom name="d39" type="mesh" mesh="dust_ball_mesh" material="dust_material" class="dust"/>
    </body>

    <body name="dust_40" pos="-0.9008 -0.1590 0.5">
      <freejoint/>
      <inertial mass="0.03" diaginertia="2e-5 2e-5 2e-5" pos="0 0 0"/>
      <geom name="d40" type="mesh" mesh="dust_ball_mesh" material="dust_material" class="dust"/>
    </body>

    <body name="dust_41" pos="-1.2500 -1.3000 0.5">
      <freejoint/>
      <inertial mass="0.03" diaginertia="2e-5 2e-5 2e-5" pos="0 0 0"/>
      <geom name="d41" type="mesh" mesh="dust_ball_mesh" material="dust_material" class="dust"/>
    </body>

    <body name="dust_42" pos="-1.0008 -0.9500 0.5">
      <freejoint/>
      <inertial mass="0.03" diaginertia="2e-5 2e-5 2e-5" pos="0 0 0"/>
      <geom name="d42" type="mesh" mesh="dust_ball_mesh" material="dust_material" class="dust"/>
    </body>

    <body name="dust_43" pos="-0.3008 -1.1000 0.5">
      <freejoint/>
      <inertial mass="0.03" diaginertia="2e-5 2e-5 2e-5" pos="0 0 0"/>
      <geom name="d43" type="mesh" mesh="dust_ball_mesh" material="dust_material" class="dust"/>
    </body>

    <body name="dust_44" pos="-2.0000 -0.5000 0.5">
      <freejoint/>
      <inertial mass="0.03" diaginertia="2e-5 2e-5 2e-5" pos="0 0 0"/>
      <geom name="d44" type="mesh" mesh="dust_ball_mesh" material="dust_material" class="dust"/>
    </body>

    <body name="dust_45" pos="-1.2000 -0.555 0.5">
      <freejoint/>
      <inertial mass="0.03" diaginertia="2e-5 2e-5 2e-5" pos="0 0 0"/>
      <geom name="d45" type="mesh" mesh="dust_ball_mesh" material="dust_material" class="dust"/>
    </body>

    <body name="dust_46" pos="-0.5000 -0.9000 0.5">
      <freejoint/>
      <inertial mass="0.03" diaginertia="2e-5 2e-5 2e-5" pos="0 0 0"/>
      <geom name="d46" type="mesh" mesh="dust_ball_mesh" material="dust_material" class="dust"/>
    </body>

    <body name="dust_47" pos="-1.2000 -0.6000 0.5">
      <freejoint/>
      <inertial mass="0.03" diaginertia="2e-5 2e-5 2e-5" pos="0 0 0"/>
      <geom name="d47" type="mesh" mesh="dust_ball_mesh" material="dust_material" class="dust"/>
    </body>

    <body name="dust_48" pos="-0.8008 -0.1800 0.5">
      <freejoint/>
      <inertial mass="0.03" diaginertia="2e-5 2e-5 2e-5" pos="0 0 0"/>
      <geom name="d48" type="mesh" mesh="dust_ball_mesh" material="dust_material" class="dust"/>
    </body>

    <body name="dust_49" pos="-1.8000 -1.1000 0.5">
      <freejoint/>
      <inertial mass="0.03" diaginertia="2e-5 2e-5 2e-5" pos="0 0 0"/>
      <geom name="d49" type="mesh" mesh="dust_ball_mesh" material="dust_material" class="dust"/>
    </body>

    <body name="dust_50" pos="-0.500 -0.2000 0.5">
      <freejoint/>
      <inertial mass="0.03" diaginertia="2e-5 2e-5 2e-5" pos="0 0 0"/>
      <geom name="d50" type="mesh" mesh="dust_ball_mesh" material="dust_material" class="dust"/>
    </body>



<!--      <body name="dust_51" pos="-1.4200 -0.7600 0.5">-->
<!--      <freejoint/>-->
<!--      <inertial mass="0.03" diaginertia="2e-5 2e-5 2e-5" pos="0 0 0"/>-->
<!--      <geom name="d51" type="mesh" mesh="dust_ball_mesh" material="dust_material" class="dust"/>-->
<!--    </body>-->

<!--    <body name="dust_52" pos="-0.6500 -0.9800 0.5">-->
<!--      <freejoint/>-->
<!--      <inertial mass="0.03" diaginertia="2e-5 2e-5 2e-5" pos="0 0 0"/>-->
<!--      <geom name="d52" type="mesh" mesh="dust_ball_mesh" material="dust_material" class="dust"/>-->
<!--    </body>-->

<!--    <body name="dust_53" pos="-2.0500 -0.3500 0.5">-->
<!--      <freejoint/>-->
<!--      <inertial mass="0.03" diaginertia="2e-5 2e-5 2e-5" pos="0 0 0"/>-->
<!--      <geom name="d53" type="mesh" mesh="dust_ball_mesh" material="dust_material" class="dust"/>-->
<!--    </body>-->

<!--    <body name="dust_54" pos="-1.2000 -1.1500 0.5">-->
<!--      <freejoint/>-->
<!--      <inertial mass="0.03" diaginertia="2e-5 2e-5 2e-5" pos="0 0 0"/>-->
<!--      <geom name="d54" type="mesh" mesh="dust_ball_mesh" material="dust_material" class="dust"/>-->
<!--    </body>-->

<!--    <body name="dust_55" pos="-0.3000 -0.4000 0.5">-->
<!--      <freejoint/>-->
<!--      <inertial mass="0.03" diaginertia="2e-5 2e-5 2e-5" pos="0 0 0"/>-->
<!--      <geom name="d55" type="mesh" mesh="dust_ball_mesh" material="dust_material" class="dust"/>-->
<!--    </body>-->

    <body name="dust_51" pos="-2.2000 -1.3000 0.5">
      <freejoint/>
      <inertial mass="0.03" diaginertia="2e-5 2e-5 2e-5" pos="0 0 0"/>
      <geom name="d51" type="mesh" mesh="dust_ball_mesh" material="dust_material" class="dust"/>
    </body>

    <body name="dust_52" pos="-1.9000 -1.1083 0.5">
      <freejoint/>
      <inertial mass="0.03" diaginertia="2e-5 2e-5 2e-5" pos="0 0 0"/>
      <geom name="d52" type="mesh" mesh="dust_ball_mesh" material="dust_material" class="dust"/>
    </body>

    <body name="dust_53" pos="-1.9000  -0.9167 0.5">
      <freejoint/>
      <inertial mass="0.03" diaginertia="2e-5 2e-5 2e-5" pos="0 0 0"/>
      <geom name="d53" type="mesh" mesh="dust_ball_mesh" material="dust_material" class="dust"/>
    </body>

    <body name="dust_54" pos="-1.9000  -0.7250 0.5">
      <freejoint/>
      <inertial mass="0.03" diaginertia="2e-5 2e-5 2e-5" pos="0 0 0"/>
      <geom name="d54" type="mesh" mesh="dust_ball_mesh" material="dust_material" class="dust"/>
    </body>

    <body name="dust_55" pos="-1.9000 -0.5333 0.5">
      <freejoint/>
      <inertial mass="0.03" diaginertia="2e-5 2e-5 2e-5" pos="0 0 0"/>
      <geom name="d55" type="mesh" mesh="dust_ball_mesh" material="dust_material" class="dust"/>
    </body>

    <body name="dust_56" pos="-1.9000 -0.3417 0.5">
      <freejoint/>
      <inertial mass="0.03" diaginertia="2e-5 2e-5 2e-5" pos="0 0 0"/>
      <geom name="d56" type="mesh" mesh="dust_ball_mesh" material="dust_material" class="dust"/>
    </body>

    <body name="dust_57" pos="-1.9000  -0.1500 0.5">
      <freejoint/>
      <inertial mass="0.03" diaginertia="2e-5 2e-5 2e-5" pos="0 0 0"/>
      <geom name="d57" type="mesh" mesh="dust_ball_mesh" material="dust_material" class="dust"/>
    </body>

    <body name="dust_58" pos="-1.9667 -1.3000 0.5">
      <freejoint/>
      <inertial mass="0.03" diaginertia="2e-5 2e-5 2e-5" pos="0 0 0"/>
      <geom name="d58" type="mesh" mesh="dust_ball_mesh" material="dust_material" class="dust"/>
    </body>

    <body name="dust_59" pos="-1.9667 -1.1083 0.5">
      <freejoint/>
      <inertial mass="0.03" diaginertia="2e-5 2e-5 2e-5" pos="0 0 0"/>
      <geom name="d59" type="mesh" mesh="dust_ball_mesh" material="dust_material" class="dust"/>
    </body>

    <body name="dust_60" pos="-1.9667 -0.9167 0.5">
      <freejoint/>
      <inertial mass="0.03" diaginertia="2e-5 2e-5 2e-5" pos="0 0 0"/>
      <geom name="d60" type="mesh" mesh="dust_ball_mesh" material="dust_material" class="dust"/>
    </body>

    <body name="dust_61" pos="-1.9667 -0.7250 0.5">
      <freejoint/>
      <inertial mass="0.03" diaginertia="2e-5 2e-5 2e-5" pos="0 0 0"/>
      <geom name="d61" type="mesh" mesh="dust_ball_mesh" material="dust_material" class="dust"/>
    </body>

    <body name="dust_62" pos="-1.9667 -0.5333 0.5">
      <freejoint/>
      <inertial mass="0.03" diaginertia="2e-5 2e-5 2e-5" pos="0 0 0"/>
      <geom name="d62" type="mesh" mesh="dust_ball_mesh" material="dust_material" class="dust"/>
    </body>

    <body name="dust_63" pos="-1.9667 -0.3417 0.5">
      <freejoint/>
      <inertial mass="0.03" diaginertia="2e-5 2e-5 2e-5" pos="0 0 0"/>
      <geom name="d63" type="mesh" mesh="dust_ball_mesh" material="dust_material" class="dust"/>
    </body>

    <body name="dust_64" pos="-1.9667 -0.1500 0.5">
      <freejoint/>
      <inertial mass="0.03" diaginertia="2e-5 2e-5 2e-5" pos="0 0 0"/>
      <geom name="d64" type="mesh" mesh="dust_ball_mesh" material="dust_material" class="dust"/>
    </body>

    <body name="dust_65" pos="-1.7333 -1.3000 0.5">
      <freejoint/>
      <inertial mass="0.03" diaginertia="2e-5 2e-5 2e-5" pos="0 0 0"/>
      <geom name="d65" type="mesh" mesh="dust_ball_mesh" material="dust_material" class="dust"/>
    </body>

    <body name="dust_66" pos="-1.7333 -1.1083 0.5">
      <freejoint/>
      <inertial mass="0.03" diaginertia="2e-5 2e-5 2e-5" pos="0 0 0"/>
      <geom name="d66" type="mesh" mesh="dust_ball_mesh" material="dust_material" class="dust"/>
    </body>

    <body name="dust_67" pos="-1.7333 -0.9167 0.5">
      <freejoint/>
      <inertial mass="0.03" diaginertia="2e-5 2e-5 2e-5" pos="0 0 0"/>
      <geom name="d67" type="mesh" mesh="dust_ball_mesh" material="dust_material" class="dust"/>
    </body>

    <body name="dust_68" pos="-1.7333 -0.7250 0.5">
      <freejoint/>
      <inertial mass="0.03" diaginertia="2e-5 2e-5 2e-5" pos="0 0 0"/>
      <geom name="d68" type="mesh" mesh="dust_ball_mesh" material="dust_material" class="dust"/>
    </body>

    <body name="dust_69" pos="-1.7333 -0.5333 0.5">
      <freejoint/>
      <inertial mass="0.03" diaginertia="2e-5 2e-5 2e-5" pos="0 0 0"/>
      <geom name="d69" type="mesh" mesh="dust_ball_mesh" material="dust_material" class="dust"/>
    </body>

    <body name="dust_70" pos="-1.7333 -0.3417 0.5">
      <freejoint/>
      <inertial mass="0.03" diaginertia="2e-5 2e-5 2e-5" pos="0 0 0"/>
      <geom name="d70" type="mesh" mesh="dust_ball_mesh" material="dust_material" class="dust"/>
    </body>

    <body name="dust_71" pos="-1.7333 -0.1500 0.5">
      <freejoint/>
      <inertial mass="0.03" diaginertia="2e-5 2e-5 2e-5" pos="0 0 0"/>
      <geom name="d71" type="mesh" mesh="dust_ball_mesh" material="dust_material" class="dust"/>
    </body>

    <body name="dust_72" pos="-1.5000 -1.3000 0.5">
      <freejoint/>
      <inertial mass="0.03" diaginertia="2e-5 2e-5 2e-5" pos="0 0 0"/>
      <geom name="d72" type="mesh" mesh="dust_ball_mesh" material="dust_material" class="dust"/>
    </body>

    <body name="dust_73" pos="-1.5000 -1.1083 0.5">
      <freejoint/>
      <inertial mass="0.03" diaginertia="2e-5 2e-5 2e-5" pos="0 0 0"/>
      <geom name="d73" type="mesh" mesh="dust_ball_mesh" material="dust_material" class="dust"/>
    </body>

    <body name="dust_74" pos="-1.5000 -0.9167 0.5">
      <freejoint/>
      <inertial mass="0.03" diaginertia="2e-5 2e-5 2e-5" pos="0 0 0"/>
      <geom name="d74" type="mesh" mesh="dust_ball_mesh" material="dust_material" class="dust"/>
    </body>

    <body name="dust_75" pos="-1.5000 -0.7250 0.5">
      <freejoint/>
      <inertial mass="0.03" diaginertia="2e-5 2e-5 2e-5" pos="0 0 0"/>
      <geom name="d75" type="mesh" mesh="dust_ball_mesh" material="dust_material" class="dust"/>
    </body>

    <body name="dust_76" pos="-1.5000 -0.5333 0.5">
      <freejoint/>
      <inertial mass="0.03" diaginertia="2e-5 2e-5 2e-5" pos="0 0 0"/>
      <geom name="d76" type="mesh" mesh="dust_ball_mesh" material="dust_material" class="dust"/>
    </body>

    <body name="dust_77" pos="-1.5000 -0.3417 0.5">
      <freejoint/>
      <inertial mass="0.03" diaginertia="2e-5 2e-5 2e-5" pos="0 0 0"/>
      <geom name="d77" type="mesh" mesh="dust_ball_mesh" material="dust_material" class="dust"/>
    </body>

    <body name="dust_78" pos="-1.5000 -0.1500 0.5">
      <freejoint/>
      <inertial mass="0.03" diaginertia="2e-5 2e-5 2e-5" pos="0 0 0"/>
      <geom name="d78" type="mesh" mesh="dust_ball_mesh" material="dust_material" class="dust"/>
    </body>

    <body name="dust_79" pos="-1.2667 -1.3000 0.5">
      <freejoint/>
      <inertial mass="0.03" diaginertia="2e-5 2e-5 2e-5" pos="0 0 0"/>
      <geom name="d79" type="mesh" mesh="dust_ball_mesh" material="dust_material" class="dust"/>
    </body>

    <body name="dust_80" pos="-1.2667 -1.1083 0.5">
      <freejoint/>
      <inertial mass="0.03" diaginertia="2e-5 2e-5 2e-5" pos="0 0 0"/>
      <geom name="d80" type="mesh" mesh="dust_ball_mesh" material="dust_material" class="dust"/>
    </body>

    <body name="dust_81" pos="-1.2667 -0.9167 0.5">
      <freejoint/>
      <inertial mass="0.03" diaginertia="2e-5 2e-5 2e-5" pos="0 0 0"/>
      <geom name="d81" type="mesh" mesh="dust_ball_mesh" material="dust_material" class="dust"/>
    </body>

    <body name="dust_82" pos="-1.2667 -0.7250 0.5">
      <freejoint/>
      <inertial mass="0.03" diaginertia="2e-5 2e-5 2e-5" pos="0 0 0"/>
      <geom name="d82" type="mesh" mesh="dust_ball_mesh" material="dust_material" class="dust"/>
    </body>

    <body name="dust_83" pos="-1.2667 -0.5333 0.5">
      <freejoint/>
      <inertial mass="0.03" diaginertia="2e-5 2e-5 2e-5" pos="0 0 0"/>
      <geom name="d83" type="mesh" mesh="dust_ball_mesh" material="dust_material" class="dust"/>
    </body>

    <body name="dust_84" pos="-1.2667 -0.3417 0.5">
      <freejoint/>
      <inertial mass="0.03" diaginertia="2e-5 2e-5 2e-5" pos="0 0 0"/>
      <geom name="d84" type="mesh" mesh="dust_ball_mesh" material="dust_material" class="dust"/>
    </body>

    <body name="dust_85" pos="-1.2667 -0.1500 0.5">
      <freejoint/>
      <inertial mass="0.03" diaginertia="2e-5 2e-5 2e-5" pos="0 0 0"/>
      <geom name="d85" type="mesh" mesh="dust_ball_mesh" material="dust_material" class="dust"/>
    </body>

    <body name="dust_86" pos="-1.0333 -1.3000 0.5">
      <freejoint/>
      <inertial mass="0.03" diaginertia="2e-5 2e-5 2e-5" pos="0 0 0"/>
      <geom name="d86" type="mesh" mesh="dust_ball_mesh" material="dust_material" class="dust"/>
    </body>

    <body name="dust_87" pos="-1.0333 -1.1083 0.5">
      <freejoint/>
      <inertial mass="0.03" diaginertia="2e-5 2e-5 2e-5" pos="0 0 0"/>
      <geom name="d87" type="mesh" mesh="dust_ball_mesh" material="dust_material" class="dust"/>
    </body>

    <body name="dust_88" pos="-1.0333 -0.9167 0.5">
      <freejoint/>
      <inertial mass="0.03" diaginertia="2e-5 2e-5 2e-5" pos="0 0 0"/>
      <geom name="d88" type="mesh" mesh="dust_ball_mesh" material="dust_material" class="dust"/>
    </body>

    <body name="dust_89" pos="-1.0333 -0.7250 0.5">
      <freejoint/>
      <inertial mass="0.03" diaginertia="2e-5 2e-5 2e-5" pos="0 0 0"/>
      <geom name="d89" type="mesh" mesh="dust_ball_mesh" material="dust_material" class="dust"/>
    </body>

    <body name="dust_90" pos="-1.0333 -0.5333 0.5">
      <freejoint/>
      <inertial mass="0.03" diaginertia="2e-5 2e-5 2e-5" pos="0 0 0"/>
      <geom name="d90" type="mesh" mesh="dust_ball_mesh" material="dust_material" class="dust"/>
    </body>

    <body name="dust_91" pos="-1.0333 -0.3417 0.5">
      <freejoint/>
      <inertial mass="0.03" diaginertia="2e-5 2e-5 2e-5" pos="0 0 0"/>
      <geom name="d91" type="mesh" mesh="dust_ball_mesh" material="dust_material" class="dust"/>
    </body>

    <body name="dust_92" pos="-1.0333 -0.1500 0.5">
      <freejoint/>
      <inertial mass="0.03" diaginertia="2e-5 2e-5 2e-5" pos="0 0 0"/>
      <geom name="d92" type="mesh" mesh="dust_ball_mesh" material="dust_material" class="dust"/>
    </body>

    <body name="dust_93" pos="-0.8000 -1.3000 0.5">
      <freejoint/>
      <inertial mass="0.03" diaginertia="2e-5 2e-5 2e-5" pos="0 0 0"/>
      <geom name="d93" type="mesh" mesh="dust_ball_mesh" material="dust_material" class="dust"/>
    </body>

    <body name="dust_94" pos="-0.8000 -1.1083 0.5">
      <freejoint/>
      <inertial mass="0.03" diaginertia="2e-5 2e-5 2e-5" pos="0 0 0"/>
      <geom name="d94" type="mesh" mesh="dust_ball_mesh" material="dust_material" class="dust"/>
    </body>

    <body name="dust_95" pos="-0.8000 -0.9167 0.5">
      <freejoint/>
      <inertial mass="0.03" diaginertia="2e-5 2e-5 2e-5" pos="0 0 0"/>
      <geom name="d95" type="mesh" mesh="dust_ball_mesh" material="dust_material" class="dust"/>
    </body>

    <body name="dust_96" pos="-0.8000 -0.7250 0.5">
      <freejoint/>
      <inertial mass="0.03" diaginertia="2e-5 2e-5 2e-5" pos="0 0 0"/>
      <geom name="d96" type="mesh" mesh="dust_ball_mesh" material="dust_material" class="dust"/>
    </body>

    <body name="dust_97" pos="-0.8000 -0.5333 0.5">
      <freejoint/>
      <inertial mass="0.03" diaginertia="2e-5 2e-5 2e-5" pos="0 0 0"/>
      <geom name="d97" type="mesh" mesh="dust_ball_mesh" material="dust_material" class="dust"/>
    </body>

    <body name="dust_98" pos="-0.8000 -0.3417 0.5">
      <freejoint/>
      <inertial mass="0.03" diaginertia="2e-5 2e-5 2e-5" pos="0 0 0"/>
      <geom name="d98" type="mesh" mesh="dust_ball_mesh" material="dust_material" class="dust"/>
    </body>

    <body name="dust_99" pos="-0.8000 -0.1500 0.5">
      <freejoint/>
      <inertial mass="0.03" diaginertia="2e-5 2e-5 2e-5" pos="0 0 0"/>
      <geom name="d99" type="mesh" mesh="dust_ball_mesh" material="dust_material" class="dust"/>
    </body>

    <body name="dust_100" pos="-1.5667 -1.3000 0.5">
      <freejoint/>
      <inertial mass="0.03" diaginertia="2e-5 2e-5 2e-5" pos="0 0 0"/>
      <geom name="d100" type="mesh" mesh="dust_ball_mesh" material="dust_material" class="dust"/>
    </body>

    <body name="dust_101" pos="-0.5667 -1.1083 0.5">
      <freejoint/>
      <inertial mass="0.03" diaginertia="2e-5 2e-5 2e-5" pos="0 0 0"/>
      <geom name="d101" type="mesh" mesh="dust_ball_mesh" material="dust_material" class="dust"/>
    </body>

    <body name="dust_102" pos="-0.5667 -0.9167 0.5">
      <freejoint/>
      <inertial mass="0.03" diaginertia="2e-5 2e-5 2e-5" pos="0 0 0"/>
      <geom name="d102" type="mesh" mesh="dust_ball_mesh" material="dust_material" class="dust"/>
    </body>

    <body name="dust_103" pos="-0.5667 -0.7250 0.5">
      <freejoint/>
      <inertial mass="0.03" diaginertia="2e-5 2e-5 2e-5" pos="0 0 0"/>
      <geom name="d103" type="mesh" mesh="dust_ball_mesh" material="dust_material" class="dust"/>
    </body>

    <body name="dust_104" pos="-0.5667 -0.5333 0.5">
      <freejoint/>
      <inertial mass="0.03" diaginertia="2e-5 2e-5 2e-5" pos="0 0 0"/>
      <geom name="d104" type="mesh" mesh="dust_ball_mesh" material="dust_material" class="dust"/>
    </body>

    <body name="dust_105" pos="-0.5667 -0.3417 0.5">
      <freejoint/>
      <inertial mass="0.03" diaginertia="2e-5 2e-5 2e-5" pos="0 0 0"/>
      <geom name="d105" type="mesh" mesh="dust_ball_mesh" material="dust_material" class="dust"/>
    </body>

    <body name="dust_106" pos="-0.5667 -0.1500 0.5">
      <freejoint/>
      <inertial mass="0.03" diaginertia="2e-5 2e-5 2e-5" pos="0 0 0"/>
      <geom name="d106" type="mesh" mesh="dust_ball_mesh" material="dust_material" class="dust"/>
    </body>

    <body name="dust_107" pos="-1.3333 -1.3000 0.5">
      <freejoint/>
      <inertial mass="0.03" diaginertia="2e-5 2e-5 2e-5" pos="0 0 0"/>
      <geom name="d107" type="mesh" mesh="dust_ball_mesh" material="dust_material" class="dust"/>
    </body>

    <body name="dust_108" pos="-0.3333 -1.1083 0.5">
      <freejoint/>
      <inertial mass="0.03" diaginertia="2e-5 2e-5 2e-5" pos="0 0 0"/>
      <geom name="d108" type="mesh" mesh="dust_ball_mesh" material="dust_material" class="dust"/>
    </body>

    <body name="dust_109" pos="-0.3333 -0.9167 0.5">
      <freejoint/>
      <inertial mass="0.03" diaginertia="2e-5 2e-5 2e-5" pos="0 0 0"/>
      <geom name="d109" type="mesh" mesh="dust_ball_mesh" material="dust_material" class="dust"/>
    </body>

    <body name="dust_110" pos="-0.3333 -0.7250 0.5">
      <freejoint/>
      <inertial mass="0.03" diaginertia="2e-5 2e-5 2e-5" pos="0 0 0"/>
      <geom name="d110" type="mesh" mesh="dust_ball_mesh" material="dust_material" class="dust"/>
    </body>

    <body name="dust_111" pos="-0.3333 -0.5333 0.5">
      <freejoint/>
      <inertial mass="0.03" diaginertia="2e-5 2e-5 2e-5" pos="0 0 0"/>
      <geom name="d111" type="mesh" mesh="dust_ball_mesh" material="dust_material" class="dust"/>
    </body>

    <body name="dust_112" pos="-0.3333 -0.3417 0.5">
      <freejoint/>
      <inertial mass="0.03" diaginertia="2e-5 2e-5 2e-5" pos="0 0 0"/>
      <geom name="d112" type="mesh" mesh="dust_ball_mesh" material="dust_material" class="dust"/>
    </body>

    <body name="dust_113" pos="-0.3333 -0.1500 0.5">
      <freejoint/>
      <inertial mass="0.03" diaginertia="2e-5 2e-5 2e-5" pos="0 0 0"/>
      <geom name="d113" type="mesh" mesh="dust_ball_mesh" material="dust_material" class="dust"/>
    </body>

    <body name="dust_114" pos="-1.7500 -1.3000 0.5">
      <freejoint/>
      <inertial mass="0.03" diaginertia="2e-5 2e-5 2e-5" pos="0 0 0"/>
      <geom name="d114" type="mesh" mesh="dust_ball_mesh" material="dust_material" class="dust"/>
    </body>

    <body name="dust_115" pos="-0.1000 -1.1083 0.5">
      <freejoint/>
      <inertial mass="0.03" diaginertia="2e-5 2e-5 2e-5" pos="0 0 0"/>
      <geom name="d115" type="mesh" mesh="dust_ball_mesh" material="dust_material" class="dust"/>
    </body>

    <body name="dust_116" pos="-0.1000 -0.9167 0.5">
      <freejoint/>
      <inertial mass="0.03" diaginertia="2e-5 2e-5 2e-5" pos="0 0 0"/>
      <geom name="d116" type="mesh" mesh="dust_ball_mesh" material="dust_material" class="dust"/>
    </body>

    <body name="dust_117" pos="-0.1000 -0.7250 0.5">
      <freejoint/>
      <inertial mass="0.03" diaginertia="2e-5 2e-5 2e-5" pos="0 0 0"/>
      <geom name="d117" type="mesh" mesh="dust_ball_mesh" material="dust_material" class="dust"/>
    </body>

    <body name="dust_118" pos="-0.1000 -0.5333 0.5">
      <freejoint/>
      <inertial mass="0.03" diaginertia="2e-5 2e-5 2e-5" pos="0 0 0"/>
      <geom name="d118" type="mesh" mesh="dust_ball_mesh" material="dust_material" class="dust"/>
    </body>

    <body name="dust_119" pos="-0.1000 -0.3417 0.5">
      <freejoint/>
      <inertial mass="0.03" diaginertia="2e-5 2e-5 2e-5" pos="0 0 0"/>
      <geom name="d119" type="mesh" mesh="dust_ball_mesh" material="dust_material" class="dust"/>
    </body>

    <body name="dust_120" pos="-0.1000 -0.1500 0.5">
      <freejoint/>
      <inertial mass="0.03" diaginertia="2e-5 2e-5 2e-5" pos="0 0 0"/>
      <geom name="d120" type="mesh" mesh="dust_ball_mesh" material="dust_material" class="dust"/>
    </body>



  </worldbody>

  <!-- ================= ACTUATORS ================= -->
  <actuator>
    <position class="position" name="shoulder_pan_act" joint="shoulder_pan"/>
    <position class="position" name="shoulder_lift_act" joint="shoulder_lift"/>
    <position class="position_limited" name="elbow_act" joint="elbow"/>
    <position class="position_small" name="wrist_1_act" joint="wrist_1"/>
    <position class="position_small" name="wrist_2_act" joint="wrist_2"/>
    <position class="position_small" name="wrist_3_act" joint="wrist_3"/>
  </actuator>
</mujoco>